<?xml version='1.0'?>

<robot name="robert" xmlns:xacro="http://www.ros.org/wiki/xacro">

  <xacro:property name="cameraSize" value="0.05"/>
  <xacro:property name="cameraMass" value="0.05"/>
  <xacro:property name="M_PI" value="3.14159265359"/>
  
  <xacro:include filename="$(find robert)/urdf/robert.gazebo"/>
  <xacro:include filename="$(find robert)/urdf/robert.material"/>
  <xacro:include filename="$(find robert)/urdf/robert_d435_properties.urdf.xacro" />

  <link name="robot_footprint"></link>

  <joint name="robot_footprint_joint" type="fixed">
    <origin xyz="0 0 0" rpy="0 0 0" />
    <parent link="robot_footprint"/>
    <child link="chassis" />
  </joint>

  <link name='chassis'>
    <pose>0 0 0.1 0 0 0</pose>

    <inertial>
      <mass value="5.0"/>
      <origin xyz="0.0 0 0.1" rpy=" 0 0 0"/>
      <inertia
          ixx="0.1" ixy="0" ixz="0"
          iyy="0.1" iyz="0"
          izz="0.1"
      />
    </inertial>

    <collision name='collision'>
      <geometry>
        <box size=".4 .2 .1"/>
      </geometry>
    </collision>

    <!-- <visual name='chassis_visual'>
      <origin xyz="0 0 0" rpy=" 0 0 0"/>
      <geometry>
        <box size=".4 .2 .1"/>
      </geometry>
      <material name="black"/>
    </visual> -->


    <visual name='chassis_visual'>
      <origin xyz="0 0 -0.05" rpy="0 0 0" />
      <geometry>
        <mesh filename="package://robert/meshes/robot_colored.dae" />
      </geometry>
      <!-- <material name="">
        <color rgba="0.79216 0.81961 0.93333 1" />
      </material> -->
    </visual>


    <collision name='caster_collision'>
      <origin xyz="-0.15 0 -0.05" rpy=" 0 0 0"/>
      <geometry>
        <sphere radius="0.05"/>
      </geometry>
      <!-- <surface>
        <friction>
          <ode>
            <mu>0</mu>
            <mu2>0</mu2>
            <slip1>1.0</slip1>
            <slip2>1.0</slip2>
          </ode>
        </friction>
      </surface> -->
    </collision>

    <visual name='caster_visual'>
      <origin xyz="-0.15 0 -0.05" rpy=" 0 0 0"/>
      <geometry>
        <sphere radius="0.05"/>
      </geometry>
    </visual>

    <collision name='caster_front_collision'>
      <origin xyz="0.15 0 -0.05" rpy=" 0 0 0"/>
      <geometry>
        <sphere radius="0.05"/>
      </geometry>
      <!-- <surface>
        <friction>
          <ode>
            <mu>0</mu>
            <mu2>0</mu2>
            <slip1>1.0</slip1>
            <slip2>1.0</slip2>
          </ode>
        </friction>
      </surface> -->
    </collision>

    <visual name='caster_front_visual'>
      <origin xyz="0.15 0 -0.05" rpy=" 0 0 0"/>
      <geometry>
        <sphere radius="0.05"/>
      </geometry>
    </visual>

  </link>


  <link name="left_wheel">
    <!--origin xyz="0.1 0.13 0.1" rpy="0 1.5707 1.5707"/-->
    <collision name="collision">
      <origin xyz="0 0 0" rpy="0 1.5707 1.5707"/>
      <geometry>
        <cylinder radius="0.1" length="0.05"/>
      </geometry>
    </collision>
    <visual name="left_wheel_visual">
      <origin xyz="0 0 0" rpy="0 1.5707 1.5707"/>
      <geometry>
        <cylinder radius="0.1" length="0.05"/>
      </geometry>
      <material name="yellow"/>
    </visual>
    <inertial>
      <origin xyz="0 0 0" rpy="0 1.5707 1.5707"/>
      <mass value="5"/>
      <inertia
        ixx=".1" ixy="0.0" ixz="0.0"
        iyy=".1" iyz="0.0"
        izz=".1"/>
    </inertial>
  </link>

  <link name="right_wheel">
    <!--origin xyz="0.1 -0.13 0.1" rpy="0 1.5707 1.5707"/-->
    <collision name="collision">
      <origin xyz="0 0 0" rpy="0 1.5707 1.5707"/>
      <geometry>
        <cylinder radius="0.1" length="0.05"/>
      </geometry>
    </collision>
    <visual name="right_wheel_visual">
      <origin xyz="0 0 0" rpy="0 1.5707 1.5707"/>
      <geometry>
        <cylinder radius="0.1" length="0.05"/>
      </geometry>
      <material name="yellow"/>
    </visual>
    <inertial>
      <origin xyz="0 0 0" rpy="0 1.5707 1.5707"/>
      <mass value="5"/>
      <inertia
        ixx=".1" ixy="0.0" ixz="0.0"
        iyy=".1" iyz="0.0"
        izz=".1"/>
    </inertial>
  </link>


  <joint type="continuous" name="left_wheel_hinge">
    <origin xyz="0 0.15 0" rpy="0 0 0"/>
    <!--origin xyz="0.1 0.13 0" rpy="0 1.5707 1.5707"/-->
    <child link="left_wheel"/>
    <parent link="chassis"/>
    <axis xyz="0 1 0" rpy="0 0 0"/>
    <!-- <limit effort="10000" velocity="1000"/> -->
    <joint_properties damping="0.0" friction="0.0"/>
  </joint>

  <joint type="continuous" name="right_wheel_hinge">
    <origin xyz="0 -0.15 0" rpy="0 0 0"/>
    <!--origin xyz="0.1 -0.13 0" rpy="0 1.5707 1.5707"/-->
    <child link="right_wheel"/>
    <parent link="chassis"/>
    <axis xyz="0 1 0" rpy="0 0 0"/>
    <!-- <limit effort="10000" velocity="1000"/> -->
    <joint_properties damping="0.0" friction="0.0"/>
  </joint>

<!-- camera2d-3d link-->

  <link name="camera_link">
    <collision>
      <origin xyz="0 0 0" rpy="0 0 0"/>
      <geometry>
        <box size="${cameraSize} ${cameraSize} ${cameraSize}"/>
      </geometry>
    </collision>

    <visual>
      <origin xyz="0 0 0" rpy="${M_PI/2} 0 ${M_PI/2}"/>
      <geometry>
        <mesh filename="package://robert/meshes/d435.dae" />
        <!-- <box size="${cameraSize} ${cameraSize} ${cameraSize}"/> -->
      </geometry>
      <material name="green"/>
    </visual>

    <inertial>
      <mass value="${cameraMass}" />
      <origin xyz="0 0 0" rpy="0 0 0"/>
      <box_inertia m="${cameraMass}" x="${cameraSize}" y="${cameraSize}" z="${cameraSize}" />
      <inertia ixx="1e-6" ixy="0" ixz="0" iyy="1e-6" iyz="0" izz="1e-6" />
    </inertial>
  </link>

  <!-- joint camera  -->

  <joint name="camera_joint" type="fixed">
    <axis xyz="0 1 0" />
    <origin xyz=".16 0 0.85" rpy="0 0 0"/>
    <parent link="chassis"/>
    <child link="camera_link"/>
  </joint>

 

    <!--~~~~~~~~ camera depth joints and links ~~~~~~~~-->
    <!-- JOINT -->
    <joint name="camera_depth_joint" type="fixed">
      <origin xyz="0 0 0" rpy="0 0 0"/>
      <parent link="camera_link"/>
      <child link="camera_depth_frame" />
    </joint>
    <!-- LINK -->
    <link name="camera_depth_frame"/>
    
    <!-- JOINT -->
    <joint name="camera_depth_optical_joint" type="fixed">
      <origin xyz="0 0 0" rpy="${-M_PI/2} 0 ${-M_PI/2}" />
      <parent link="camera_depth_frame" />
      <child link="camera_depth_optical_frame" />
    </joint>
    <!-- LINK -->
    <link name="camera_depth_optical_frame"/>
    
    <!--~~~~~~~~ camera left IR joints and links ~~~~~~~~-->
    <!-- JOINT -->
    <joint name="camera_left_ir_joint" type="fixed">
      <origin xyz="0 ${d435_cam_depth_to_left_ir_offset} 0" rpy="0 0 0" />
      <parent link="camera_depth_frame" />
      <child link="camera_left_ir_frame" />
    </joint>
    <!-- LINK -->
    <link name="camera_left_ir_frame"/>

    <!-- JOINT -->
    <joint name="camera_left_ir_optical_joint" type="fixed">
      <origin xyz="0 0 0" rpy="${-M_PI/2} 0 ${-M_PI/2}" />
      <parent link="camera_left_ir_frame" />
      <child link="camera_left_ir_optical_frame" />
    </joint>
    <!-- LINK -->
    <link name="camera_left_ir_optical_frame"/>

    <!--~~~~~~~~ camera right IR joints and links ~~~~~~~~-->
    <!-- JOINT -->
    <joint name="camera_right_ir_joint" type="fixed">
      <origin xyz="0 ${d435_cam_depth_to_right_ir_offset} 0" rpy="0 0 0" />
      <parent link="camera_depth_frame" />
      <child link="camera_right_ir_frame" />
    </joint>
    <!-- LINK -->
    <link name="camera_right_ir_frame"/>

    <!-- JOINT -->
    <joint name="camera_right_ir_optical_joint" type="fixed">
      <origin xyz="0 0 0" rpy="${-M_PI/2} 0 ${-M_PI/2}" />
      <parent link="camera_right_ir_frame" />
      <child link="camera_right_ir_optical_frame" />
    </joint>
    <!-- LINK -->
    <link name="camera_right_ir_optical_frame"/>

    <!--~~~~~~~~ camera color joints and links ~~~~~~~~-->
    <!-- JOINT -->
    <joint name="camera_color_joint" type="fixed">
      <origin xyz="0 ${d435_cam_depth_to_color_offset} 0" rpy="0 0 0" />
      <parent link="camera_depth_frame" />
      <child link="camera_color_frame" />
    </joint>
    <!-- LINK -->
    <link name="camera_color_frame"/>

    <!-- JOINT -->
    <joint name="camera_color_optical_joint" type="fixed">
      <origin xyz="0 0 0" rpy="${-M_PI/2} 0 ${-M_PI/2}" />
      <parent link="camera_color_frame" />
      <child link="camera_color_optical_frame" />
    </joint>
    <!-- LINK -->
    <link name="camera_color_optical_frame"/>

    <!--~~~~~~~~ End of camera depth joints and links ~~~~~~~~-->


  <!-- Hokuyo Laser -->
  <link name="hokuyo_link">
    <collision>
      <origin xyz="0 0 0" rpy="0 0 0"/>
      <geometry>
    <box size="0.1 0.1 0.1"/>
      </geometry>
    </collision>

    <visual>
      <origin xyz="0 0 0" rpy="0 0 0"/>
      <geometry>
        <mesh filename="package://robert/meshes/hokuyo.dae"/>
      </geometry>
    </visual>

    <inertial>
      <mass value="1e-5" />
      <origin xyz="0 0 0" rpy="0 0 0"/>
      <inertia ixx="1e-6" ixy="0" ixz="0" iyy="1e-6" iyz="0" izz="1e-6" />
    </inertial>
  </link>

  <joint name="hokuyo_joint" type="fixed">
    <axis xyz="0 1 0" />
    <origin xyz="0.0 0 0.1" rpy="0 0 0"/>
    <parent link="chassis"/>
    <child link="hokuyo_link"/>
  </joint> 



</robot>

